Workbook

Sheet Deckblatt

Sheet Impressum
A4: Impressum
A6: Produktlinie/Reihe: | B6: Tabellen
A8: Produkt-ID: | B8: 729
A10: Titel: | B10: Ausgaben für aktive und passive Leistungen im SGB II (Jahreszahlen)
A12: Region: | B12: Deutschland, West/Ost, Länder und Jobcenter (Gebietsstand Dezember 2024)
A14: Berichtsmonat: | B14: 2024 (Kalenderjahr)
A16: Erstellungsdatum: | B16: 45978
A18: Periodizität: | B18: jährlich
A20: Nächster Veröffentlichungstermin: | B20: 46353
A22: Hinweise: | B22: Für Zwecke der maschinellen Lesbarkeit enthält diese Datei beim Öffnen ausgeblendete Arbeitsblätter mit den unformatierten und nicht gefilterten Grundlagendaten.
A24: Herausgeberin: | B24: Bundesagentur für Arbeit
B25: Statistik
A26: Rückfragen an: | B26: Zentraler Statistik-Service
B27: Regensburger Straße 104
B28: 90478 Nürnberg
A29: E-Mail: | B29: Zentraler-Statistik-Service@arbeitsagentur.de
A30: Hotline: | B30: 0911/179-3632
A33: Internet: | B33: https://statistik.arbeitsagentur.de
A35: Zitierhinweis: | B35: Statistik der Bundesagentur für Arbeit
A38: Nutzungsbedingungen: | B38: © Statistik der Bundesagentur für Arbeit
B39: Die Produkte unterliegen dem Urheberrecht (siehe Impressum).
B40: Daten und Tabellen dürfen uneingeschränkt verwendet werden. Informationen dürfen (auch auszugsweise) gespeichert und mit Quellenangabe weitergegeben, vervielfältigt und verbreitet werden. Die Inhalte dürfen nicht verändert oder verfälscht werden. Eigene Berechnungen sind erlaubt, jedoch als solche kenntlich zu machen. Im Fall einer Veröffentlichung im Internet soll dies mit einer Verlinkung auf die Homepage der Statistik der Bundesagentur für Arbeit erfolgen.

Sheet Inhaltsverzeichnis
F1: Ausgaben im SGB II
A4: Inhaltsverzeichnis
A7: Ausgaben für aktive und passive Leistungen im SGB II (Jahreszahlen)
A8: Deutschland, West/Ost, Länder und Jobcenter (Gebietsstand Dezember 2024)
A9: 2024 (Kalenderjahr)
A11: Tabelle
A13: 1 | B13: Ausgaben für aktive und passive Leistungen im SGB II
A14: 2 | B14: Ausgaben für aktive und passive Leistungen im SGB II - Regionenvergleich
A15: 3 | B15: Eckwerte der Grundsicherung im SGB II
A16: 4 | B16: Zahlungsansprüche im SGB II
A18: Methodische Hinweise
A19: Glossar
A20: Statistik-Infoseite

Sheet 1
I1: Ausgaben im SGB II
A3: Tabelle 1: Ausgaben für aktive und passive Leistungen im SGB II | H3: zurück zum Inhalt
A4: =Steuerung_Eckwerte!C3 -> Deutschland
A5: Jahressumme 2024
A8: Über die Auswahlliste kann die Region ausgesucht werden.
A9: =IF(Steuerung_Eckwerte!E3="H1",Steuerung_Eckwerte!I6,IF(Steuerung_Eckwerte!E3="H2",Steuerung_Eckwerte!I6," ")) -> Mit Ausnahme der Ausgaben für Bildung und Teilhabe wurden die Informationen für Deutschland, Ost- und Westdeutschland sowie die Bundesländer um die unplausiblen bzw. nicht vorhandenen Daten einzelner Jobcenter hochgerechnet. Für unplausible bzw. unvollständige Datenlieferungen im Bereich Eingliederungsleistungen wird bereits auf Jobcenter-Ebene ein Schätzwert gebildet.
A10: =IF(Steuerung_Eckwerte!E3="H1",Steuerung_Eckwerte!I4,IF(Steuerung_Eckwerte!E3="H2",Steuerung_Eckwerte!I5," ")) -> Die Daten für Deutschland insgesamt beinhalten die Buchungen der Jobcenter zuzüglich der Buchungen der Regionaldirektionen, der besonderen Dienststellen und SGB III-Dienststellen (BA) auf Finanzpositionen des SGB II.
D12: 2024 | F12: 2023 | H12: Veränderung der Ausgaben gegenüber dem Vorjahr
D13: Ausgaben | E13: Anteil an Insgesamt in % | F13: Ausgaben | G13: Anteil an Insgesamt in % | H13: absolut | I13: in %
D14: 1 | E14: 2 | F14: 3 | G14: 4 | H14: 5 | I14: 6
A15: =IF(Steuerung_Eckwerte!E3= 1, "Insgesamt 2)", "Insgesamt") -> Insgesamt | C15: Insgesamt (ohne B&T) | D15: =INDEX(Daten!$K$7:$R$430,MATCH(Steuerung_Eckwerte!B$3,Daten!$C$7:$C$430,0),MATCH(C15,Daten!$K$6:$R$6,0)) -> 5.708992e+10 | E15: =IF(ISERROR(D15/D$15),"X",D15/D$15*100) -> 100 | F15: =INDEX(Daten!$S$7:$Z$430,MATCH(Steuerung_Eckwerte!B$3,Daten!$C$7:$C$430,0),MATCH(C15,Daten!$S$6:$Z$6,0)) -> 5.2599183e+10 | G15: =IF(ISERROR(F15/F$15),"X",F15/F$15*100) -> 100 | H15: =INDEX(Daten!$AA$7:$AH$429,MATCH(Steuerung_Eckwerte!B$3,Daten!$C$7:$C$429,0),MATCH(C15,Daten!$AA$6:$AH$6,0)) -> 4.4907374e+09 | I15: =IF(INDEX(Daten!$AI$7:$AP$429,MATCH(Steuerung_Eckwerte!B$3,Daten!$C$7:$C$429,0),MATCH(C15,Daten!$AI$6:$AP$6,0))="X","X",IF(OR(INDEX(Daten!$AI$7:$AP$429,MATCH(Steuerung_Eckwerte!B$3,Daten!$C$7:$C$429,0),MATCH(C15,Daten!$AI$6:$AP$6,0))<(-250),INDEX(Daten!$AI$7:$AP$429,MATCH(Steuerung_Eckwerte!B$3,Daten!$C$7:$C$429,0),MATCH(C15,Daten!$AI$6:$AP$6,0))>250),".X",INDEX(Daten!$AI$7:$AP$429,MATCH(Steuerung_Eckwerte!B$3,Daten!$C$7:$C$429,0),MATCH(C15,Daten!$AI$6:$AP$6,0)))) -> 8.5376563
A16: dav. | B16: Bürgergeld | C16: Bürgergeld (ohne Altfälle) | D16: =INDEX(Daten!$K$7:$R$430,MATCH(Steuerung_Eckwerte!B$3,Daten!$C$7:$C$430,0),MATCH(C16,Daten!$K$6:$R$6,0)) -> 2.2057313e+10 | E16: =IF(ISERROR(D16/D$15),"X",D16/D$15*100) -> 38.63609 | F16: =INDEX(Daten!$S$7:$Z$430,MATCH(Steuerung_Eckwerte!B$3,Daten!$C$7:$C$430,0),MATCH(C16,Daten!$S$6:$Z$6,0)) -> 1.913887e+10 | G16: =IF(ISERROR(F16/F$15),"X",F16/F$15*100) -> 36.38625 | H16: =INDEX(Daten!$AA$7:$AH$429,MATCH(Steuerung_Eckwerte!B$3,Daten!$C$7:$C$429,0),MATCH(C16,Daten!$AA$6:$AH$6,0)) -> 2.9184427e+09 | I16: =IF(INDEX(Daten!$AI$7:$AP$429,MATCH(Steuerung_Eckwerte!B$3,Daten!$C$7:$C$429,0),MATCH(C16,Daten!$AI$6:$AP$6,0))="X","X",IF(OR(INDEX(Daten!$AI$7:$AP$429,MATCH(Steuerung_Eckwerte!B$3,Daten!$C$7:$C$429,0),MATCH(C16,Daten!$AI$6:$AP$6,0))<(-250),INDEX(Daten!$AI$7:$AP$429,MATCH(Steuerung_Eckwerte!B$3,Daten!$C$7:$C$429,0),MATCH(C16,Daten!$AI$6:$AP$6,0))>250),".X",INDEX(Daten!$AI$7:$AP$429,MATCH(Steuerung_Eckwerte!B$3,Daten!$C$7:$C$429,0),MATCH(C16,Daten!$AI$6:$AP$6,0)))) -> 15.248772
B17: Kosten der Unterkunft | C17: Kosten der Unterkunft | D17: =INDEX(Daten!$K$7:$R$430,MATCH(Steuerung_Eckwerte!B$3,Daten!$C$7:$C$430,0),MATCH(C17,Daten!$K$6:$R$6,0)) -> 1.7474337e+10 | E17: =IF(ISERROR(D17/D$15),"X",D17/D$15*100) -> 30.608446 | F17: =INDEX(Daten!$S$7:$Z$430,MATCH(Steuerung_Eckwerte!B$3,Daten!$C$7:$C$430,0),MATCH(C17,Daten!$S$6:$Z$6,0)) -> 1.6520604e+10 | G17: =IF(ISERROR(F17/F$15),"X",F17/F$15*100) -> 31.408481 | H17: =INDEX(Daten!$AA$7:$AH$429,MATCH(Steuerung_Eckwerte!B$3,Daten!$C$7:$C$429,0),MATCH(C17,Daten!$AA$6:$AH$6,0)) -> 9.5373295e+08 | I17: =IF(INDEX(Daten!$AI$7:$AP$429,MATCH(Steuerung_Eckwerte!B$3,Daten!$C$7:$C$429,0),MATCH(C17,Daten!$AI$6:$AP$6,0))="X","X",IF(OR(INDEX(Daten!$AI$7:$AP$429,MATCH(Steuerung_Eckwerte!B$3,Daten!$C$7:$C$429,0),MATCH(C17,Daten!$AI$6:$AP$6,0))<(-250),INDEX(Daten!$AI$7:$AP$429,MATCH(Steuerung_Eckwerte!B$3,Daten!$C$7:$C$429,0),MATCH(C17,Daten!$AI$6:$AP$6,0))>250),".X",INDEX(Daten!$AI$7:$AP$429,MATCH(Steuerung_Eckwerte!B$3,Daten!$C$7:$C$429,0),MATCH(C17,Daten!$AI$6:$AP$6,0)))) -> 5.7729907
B18: Ausgaben für Leistungen zur Sozialversicherung | C18: Ausgaben für Leistungen zur Sozialversicherung | D18: =INDEX(Daten!$K$7:$R$430,MATCH(Steuerung_Eckwerte!B$3,Daten!$C$7:$C$430,0),MATCH(C18,Daten!$K$6:$R$6,0)) -> 7.1652477e+09 | E18: =IF(ISERROR(D18/D$15),"X",D18/D$15*100) -> 12.55081 | F18: =INDEX(Daten!$S$7:$Z$430,MATCH(Steuerung_Eckwerte!B$3,Daten!$C$7:$C$430,0),MATCH(C18,Daten!$S$6:$Z$6,0)) -> 6.686731e+09 | G18: =IF(ISERROR(F18/F$15),"X",F18/F$15*100) -> 12.712614 | H18: =INDEX(Daten!$AA$7:$AH$429,MATCH(Steuerung_Eckwerte!B$3,Daten!$C$7:$C$429,0),MATCH(C18,Daten!$AA$6:$AH$6,0)) -> 4.7851671e+08 | I18: =IF(INDEX(Daten!$AI$7:$AP$429,MATCH(Steuerung_Eckwerte!B$3,Daten!$C$7:$C$429,0),MATCH(C18,Daten!$AI$6:$AP$6,0))="X","X",IF(OR(INDEX(Daten!$AI$7:$AP$429,MATCH(Steuerung_Eckwerte!B$3,Daten!$C$7:$C$429,0),MATCH(C18,Daten!$AI$6:$AP$6,0))<(-250),INDEX(Daten!$AI$7:$AP$429,MATCH(Steuerung_Eckwerte!B$3,Daten!$C$7:$C$429,0),MATCH(C18,Daten!$AI$6:$AP$6,0))>250),".X",INDEX(Daten!$AI$7:$AP$429,MATCH(Steuerung_Eckwerte!B$3,Daten!$C$7:$C$429,0),MATCH(C18,Daten!$AI$6:$AP$6,0)))) -> 7.156213
B19: Eingliederungsleistungen ¹ | C19: Eingliederungsleistungen | D19: =INDEX(Daten!$K$7:$R$430,MATCH(Steuerung_Eckwerte!B$3,Daten!$C$7:$C$430,0),MATCH(C19,Daten!$K$6:$R$6,0)) -> 3.6835652e+09 | E19: =IF(ISERROR(D19/D$15),"X",D19/D$15*100) -> 6.4522164 | F19: =INDEX(Daten!$S$7:$Z$430,MATCH(Steuerung_Eckwerte!B$3,Daten!$C$7:$C$430,0),MATCH(C19,Daten!$S$6:$Z$6,0)) -> 3.8131858e+09 | G19: =IF(ISERROR(F19/F$15),"X",F19/F$15*100) -> 7.2495152 | H19: =INDEX(Daten!$AA$7:$AH$429,MATCH(Steuerung_Eckwerte!B$3,Daten!$C$7:$C$429,0),MATCH(C19,Daten!$AA$6:$AH$6,0)) -> -1.2962056e+08 | I19: =IF(INDEX(Daten!$AI$7:$AP$429,MATCH(Steuerung_Eckwerte!B$3,Daten!$C$7:$C$429,0),MATCH(C19,Daten!$AI$6:$AP$6,0))="X","X",IF(OR(INDEX(Daten!$AI$7:$AP$429,MATCH(Steuerung_Eckwerte!B$3,Daten!$C$7:$C$429,0),MATCH(C19,Daten!$AI$6:$AP$6,0))<(-250),INDEX(Daten!$AI$7:$AP$429,MATCH(Steuerung_Eckwerte!B$3,Daten!$C$7:$C$429,0),MATCH(C19,Daten!$AI$6:$AP$6,0))>250),".X",INDEX(Daten!$AI$7:$AP$429,MATCH(Steuerung_Eckwerte!B$3,Daten!$C$7:$C$429,0),MATCH(C19,Daten!$AI$6:$AP$6,0)))) -> -3.3992721
B20: Verwaltungskosten ² ³ | C20: Verwaltungskosten | D20: =INDEX(Daten!$K$7:$R$430,MATCH(Steuerung_Eckwerte!B$3,Daten!$C$7:$C$430,0),MATCH(C20,Daten!$K$6:$R$6,0)) -> 6.4482995e+09 | E20: =IF(ISERROR(D20/D$15),"X",D20/D$15*100) -> 11.294988 | F20: =INDEX(Daten!$S$7:$Z$430,MATCH(Steuerung_Eckwerte!B$3,Daten!$C$7:$C$430,0),MATCH(C20,Daten!$S$6:$Z$6,0)) -> 6.139999e+09 | G20: =IF(ISERROR(F20/F$15),"X",F20/F$15*100) -> 11.673183 | H20: =INDEX(Daten!$AA$7:$AH$429,MATCH(Steuerung_Eckwerte!B$3,Daten!$C$7:$C$429,0),MATCH(C20,Daten!$AA$6:$AH$6,0)) -> 3.0830053e+08 | I20: =IF(INDEX(Daten!$AI$7:$AP$429,MATCH(Steuerung_Eckwerte!B$3,Daten!$C$7:$C$429,0),MATCH(C20,Daten!$AI$6:$AP$6,0))="X","X",IF(OR(INDEX(Daten!$AI$7:$AP$429,MATCH(Steuerung_Eckwerte!B$3,Daten!$C$7:$C$429,0),MATCH(C20,Daten!$AI$6:$AP$6,0))<(-250),INDEX(Daten!$AI$7:$AP$429,MATCH(Steuerung_Eckwerte!B$3,Daten!$C$7:$C$429,0),MATCH(C20,Daten!$AI$6:$AP$6,0))>250),".X",INDEX(Daten!$AI$7:$AP$429,MATCH(Steuerung_Eckwerte!B$3,Daten!$C$7:$C$429,0),MATCH(C20,Daten!$AI$6:$AP$6,0)))) -> 5.0211822
B21: Abweichend zu erbringende Leistungen | C21: Abweichend zu erbringende Leistungen | D21: =INDEX(Daten!$K$7:$R$430,MATCH(Steuerung_Eckwerte!B$3,Daten!$C$7:$C$430,0),MATCH(C21,Daten!$K$6:$R$6,0)) -> 2.6115767e+08 | E21: =IF(ISERROR(D21/D$15),"X",D21/D$15*100) -> 0.4574497 | F21: =INDEX(Daten!$S$7:$Z$430,MATCH(Steuerung_Eckwerte!B$3,Daten!$C$7:$C$430,0),MATCH(C21,Daten!$S$6:$Z$6,0)) -> 2.9979254e+08 | G21: =IF(ISERROR(F21/F$15),"X",F21/F$15*100) -> 0.56995665 | H21: =INDEX(Daten!$AA$7:$AH$429,MATCH(Steuerung_Eckwerte!B$3,Daten!$C$7:$C$429,0),MATCH(C21,Daten!$AA$6:$AH$6,0)) -> -38634869 | I21: =IF(INDEX(Daten!$AI$7:$AP$429,MATCH(Steuerung_Eckwerte!B$3,Daten!$C$7:$C$429,0),MATCH(C21,Daten!$AI$6:$AP$6,0))="X","X",IF(OR(INDEX(Daten!$AI$7:$AP$429,MATCH(Steuerung_Eckwerte!B$3,Daten!$C$7:$C$429,0),MATCH(C21,Daten!$AI$6:$AP$6,0))<(-250),INDEX(Daten!$AI$7:$AP$429,MATCH(Steuerung_Eckwerte!B$3,Daten!$C$7:$C$429,0),MATCH(C21,Daten!$AI$6:$AP$6,0))>250),".X",INDEX(Daten!$AI$7:$AP$429,MATCH(Steuerung_Eckwerte!B$3,Daten!$C$7:$C$429,0),MATCH(C21,Daten!$AI$6:$AP$6,0)))) -> -12.887202
A22: nachrichtlich: Leistungen für Bildung und Teilhabe ⁴ | C22: Bildung und Teilhabe | D22: =INDEX(Daten!$K$7:$R$430,MATCH(Steuerung_Eckwerte!B$3,Daten!$C$7:$C$430,0),MATCH(C22,Daten!$K$6:$R$6,0)) -> X | E22: X | F22: =INDEX(Daten!$S$7:$Z$430,MATCH(Steuerung_Eckwerte!B$3,Daten!$C$7:$C$430,0),MATCH(C22,Daten!$S$6:$Z$6,0)) -> X | G22: X | H22: =INDEX(Daten!$AA$7:$AH$429,MATCH(Steuerung_Eckwerte!B$3,Daten!$C$7:$C$429,0),MATCH(C22,Daten!$AA$6:$AH$6,0)) -> X | I22: =IF(INDEX(Daten!$AI$7:$AP$429,MATCH(Steuerung_Eckwerte!B$3,Daten!$C$7:$C$429,0),MATCH(C22,Daten!$AI$6:$AP$6,0))="X","X",IF(OR(INDEX(Daten!$AI$7:$AP$429,MATCH(Steuerung_Eckwerte!B$3,Daten!$C$7:$C$429,0),MATCH(C22,Daten!$AI$6:$AP$6,0))<(-250),INDEX(Daten!$AI$7:$AP$429,MATCH(Steuerung_Eckwerte!B$3,Daten!$C$7:$C$429,0),MATCH(C22,Daten!$AI$6:$AP$6,0))>250),".X",INDEX(Daten!$AI$7:$AP$429,MATCH(Steuerung_Eckwerte!B$3,Daten!$C$7:$C$429,0),MATCH(C22,Daten!$AI$6:$AP$6,0)))) -> X
I23: © Statistik der Bundesagentur für Arbeit
A25: =Steuerung_Eckwerte!I10 -> ¹ Umfasst alle Eingliederungsleistungen nach § 16 ff. SGB II (ohne kommunale Eingliederungsleistungen gem. § 16a SGB II), die durch den Bund erstattungsfähig sind. Die Kosten für die Eignungsfeststellung nach § 16 SGB II in Verbindung mit § 32 SGB III können sowohl über das Verwaltungsbudget als auch als Eingliederungsleistung abgerechnet werden.
A26: =Steuerung_Eckwerte!I11 -> ² Die Ausgaben für überörtliche Verwaltungsaufgaben der BA sowie für sonstige überörtlich wahrzunehmende Aufgaben der BA (z.B. SGB II-Statistik) und Sonderbedarfe (z.B. für Organisationsänderungen gemäß § 6a Absatz 7 SGB II und für die Umsetzung der Bundesprogramme) sind nicht enthalten.
A27: =Steuerung_Eckwerte!I12 -> ³ Die Verwaltungsausgaben beinhalten nicht den kommunalen Finanzierungsanteil.
A28: =Steuerung_Eckwerte!I13 -> ⁴ Für die Leistungen für Bildung und Teilhabe nach § 28 SGB II besteht noch keine vollständige Datenübermittlung. Aus diesem Grund werden die Ausgaben für Bildung und Teilhabe nur nachrichtlich für die einzelnen Jobcenter berichtet und fließen daher auch nicht in die Insgesamtsumme ein. Es werden keine Summen für Deutschland, Westdeutschland, Ostdeutschland und für die Bundesländer gebildet. Ein Vorjahresvergleich ist nur eingeschränkt möglich.
A29: =Steuerung_Eckwerte!I14 -> ⁵ Aufgrund von Änderungen in der Regionalzuordnung von Gemeinden zu Jobcentern ist ein Vergleich mit dem Vorjahr nur eingeschränkt möglich.
A32: =Steuerung_Eckwerte!I23 -> ⁶ Trägerfusion: Die Daten beziehen sich auf den Gebietsstand zum Dezember 2022. Die Daten für das Jahr 2021 wurden auf den neuen Gebietsstand umgerechnet.
A34: Grafik 1: Anteile der Ausgabearten an allen Ausgaben im SGB II in %
A35: =Steuerung_Eckwerte!C3 -> Deutschland
A36: =A5 -> Jahressumme 2024

Sheet 2
L1: Ausgaben im SGB II
A3: Tabelle 2: Ausgaben für aktive und passive Leistungen im SGB II - Regionenvergleich | K3: zurück zum Inhalt
A4: Deutschland, West/Ost, Länder und Jobcenter (Gebietsstand Dezember 2024)
A5: Jahressumme 2024
A7: =Steuerung_Eckwerte!I6 -> Mit Ausnahme der Ausgaben für Bildung und Teilhabe wurden die Informationen für Deutschland, Ost- und Westdeutschland sowie die Bundesländer um die unplausiblen bzw. nicht vorhandenen Daten einzelner Jobcenter hochgerechnet. Für unplausible bzw. unvollständige Datenlieferungen im Bereich Eingliederungsleistungen wird bereits auf Jobcenter-Ebene ein Schätzwert gebildet.
A8: =Steuerung_Eckwerte!I4 -> Die Daten für Deutschland insgesamt beinhalten die Buchungen der Jobcenter zuzüglich der Buchungen der Regionaldirektionen, der besonderen Dienststellen und SGB III-Dienststellen (BA) auf Finanzpositionen des SGB II.
A9: =Steuerung_Eckwerte!I5 -> Die Daten für Ost- und Westdeutschland sowie der Bundesländer beinhalten die Buchungen der Jobcenter zuzüglich der Buchungen der SGB III-Dienststellen (BA) auf Finanzpositionen des SGB II. Buchungen der besonderen Dienststellen sowie der Regionaldirektionen sind nicht enthalten.
E11: Insgesamt | F11: dav. (Sp. 1) | L11: nachrichtlich: Leistungen für Bildung und Teilhabe ⁴
A12: Region | B12: Tr Nr | C12: Bundes- land | D12: Ver- gleichs- typ | F12: Bürgergeld | G12: Kosten der Unterkunft | H12: Ausgaben für Leistungen zur Sozialver- sicherung | I12: Einglie- derungs- leistungen ¹ | J12: Verwaltungs- kosten ² ³ | K12: Abweichend zu erbringende Leistungen
E13: 1 | F13: 2 | G13: 3 | H13: 4 | I13: 5 | J13: 6 | K13: 7 | L13: 8
A14: =Daten!C7 -> Deutschland | B14: =Daten!A7 -> D | C14: =Daten!F7 -> D | E14: =INDEX(Daten!$R$7:$R$429,MATCH('2'!B14,Daten!$A$7:$A$429,0)) -> 5.708992e+10 | F14: =INDEX(Daten!$M$7:$M$429,MATCH('2'!B14,Daten!$A$7:$A$429,0)) -> 2.2057313e+10 | G14: =INDEX(Daten!$N$7:$N$429,MATCH('2'!B14,Daten!$A$7:$A$429,0)) -> 1.7474337e+10 | H14: =INDEX(Daten!$P$7:$P$429,MATCH('2'!B14,Daten!$A$7:$A$429,0)) -> 7.1652477e+09 | I14: =INDEX(Daten!$L$7:$L$429,MATCH('2'!B14,Daten!$A$7:$A$429,0)) -> 3.6835652e+09 | J14: =INDEX(Daten!$K$7:$K$429,MATCH('2'!B14,Daten!$A$7:$A$429,0)) -> 6.4482995e+09 | K14: =INDEX(Daten!$O$7:$O$429,MATCH('2'!B14,Daten!$A$7:$A$429,0)) -> 2.6115767e+08 | L14: =INDEX(Daten!$Q$7:$Q$429,MATCH('2'!B14,Daten!$A$7:$A$429,0)) -> X
A15: =Daten!C8 -> Westdeutschland | B15: =Daten!A8 -> W | C15: =Daten!F8 -> W | E15: =INDEX(Daten!$R$7:$R$429,MATCH('2'!B15,Daten!$A$7:$A$429,0)) -> 4.392604e+10 | F15: =INDEX(Daten!$M$7:$M$429,MATCH('2'!B15,Daten!$A$7:$A$429,0)) -> 1.6936316e+10 | G15: =INDEX(Daten!$N$7:$N$429,MATCH('2'!B15,Daten!$A$7:$A$429,0)) -> 1.3642556e+10 | H15: =INDEX(Daten!$P$7:$P$429,MATCH('2'!B15,Daten!$A$7:$A$429,0)) -> 5.5042137e+09 | I15: =INDEX(Daten!$L$7:$L$429,MATCH('2'!B15,Daten!$A$7:$A$429,0)) -> 2.7969838e+09 | J15: =INDEX(Daten!$K$7:$K$429,MATCH('2'!B15,Daten!$A$7:$A$429,0)) -> 4.8514269e+09 | K15: =INDEX(Daten!$O$7:$O$429,MATCH('2'!B15,Daten!$A$7:$A$429,0)) -> 1.9454309e+08 | L15: =INDEX(Daten!$Q$7:$Q$429,MATCH('2'!B15,Daten!$A$7:$A$429,0)) -> X
A16: =Daten!C9 -> Ostdeutschland | B16: =Daten!A9 -> O | C16: =Daten!F9 -> O | E16: =INDEX(Daten!$R$7:$R$429,MATCH('2'!B16,Daten!$A$7:$A$429,0)) -> 1.3163631e+10 | F16: =INDEX(Daten!$M$7:$M$429,MATCH('2'!B16,Daten!$A$7:$A$429,0)) -> 5.1209971e+09 | G16: =INDEX(Daten!$N$7:$N$429,MATCH('2'!B16,Daten!$A$7:$A$429,0)) -> 3.8317814e+09 | H16: =INDEX(Daten!$P$7:$P$429,MATCH('2'!B16,Daten!$A$7:$A$429,0)) -> 1.6607843e+09 | I16: =INDEX(Daten!$L$7:$L$429,MATCH('2'!B16,Daten!$A$7:$A$429,0)) -> 8.8658143e+08 | J16: =INDEX(Daten!$K$7:$K$429,MATCH('2'!B16,Daten!$A$7:$A$429,0)) -> 1.5968726e+09 | K16: =INDEX(Daten!$O$7:$O$429,MATCH('2'!B16,Daten!$A$7:$A$429,0)) -> 66614581 | L16: =INDEX(Daten!$Q$7:$Q$429,MATCH('2'!B16,Daten!$A$7:$A$429,0)) -> X
A17: =Daten!C10 -> Schleswig-Holstein | B17: =Daten!A10 -> 01 | C17: =Daten!F10 -> 01 | E17: =INDEX(Daten!$R$7:$R$429,MATCH('2'!B17,Daten!$A$7:$A$429,0)) -> 1.992957e+09 | F17: =INDEX(Daten!$M$7:$M$429,MATCH('2'!B17,Daten!$A$7:$A$429,0)) -> 7.5816658e+08 | G17: =INDEX(Daten!$N$7:$N$429,MATCH('2'!B17,Daten!$A$7:$A$429,0)) -> 6.1669803e+08 | H17: =INDEX(Daten!$P$7:$P$429,MATCH('2'!B17,Daten!$A$7:$A$429,0)) -> 2.5403216e+08 | I17: =INDEX(Daten!$L$7:$L$429,MATCH('2'!B17,Daten!$A$7:$A$429,0)) -> 1.2317052e+08 | J17: =INDEX(Daten!$K$7:$K$429,MATCH('2'!B17,Daten!$A$7:$A$429,0)) -> 2.3318588e+08 | K17: =INDEX(Daten!$O$7:$O$429,MATCH('2'!B17,Daten!$A$7:$A$429,0)) -> 7703793.3 | L17: =INDEX(Daten!$Q$7:$Q$429,MATCH('2'!B17,Daten!$A$7:$A$429,0)) -> X
A18: =Daten!C11 -> Hamburg | B18: =Daten!A11 -> 02 | C18: =Daten!F11 -> 02 | E18: =INDEX(Daten!$R$7:$R$429,MATCH('2'!B18,Daten!$A$7:$A$429,0)) -> 2.2194536e+09 | F18: =INDEX(Daten!$M$7:$M$429,MATCH('2'!B18,Daten!$A$7:$A$429,0)) -> 7.6029079e+08 | G18: =INDEX(Daten!$N$7:$N$429,MATCH('2'!B18,Daten!$A$7:$A$429,0)) -> 8.5394905e+08 | H18: =INDEX(Daten!$P$7:$P$429,MATCH('2'!B18,Daten!$A$7:$A$429,0)) -> 2.4685997e+08 | I18: =INDEX(Daten!$L$7:$L$429,MATCH('2'!B18,Daten!$A$7:$A$429,0)) -> 1.5194415e+08 | J18: =INDEX(Daten!$K$7:$K$429,MATCH('2'!B18,Daten!$A$7:$A$429,0)) -> 1.9823893e+08 | K18: =INDEX(Daten!$O$7:$O$429,MATCH('2'!B18,Daten!$A$7:$A$429,0)) -> 8170745.2 | L18: =INDEX(Daten!$Q$7:$Q$429,MATCH('2'!B18,Daten!$A$7:$A$429,0)) -> X
A19: =Daten!C12 -> Niedersachsen | B19: =Daten!A12 -> 03 | C19: =Daten!F12 -> 03 | E19: =INDEX(Daten!$R$7:$R$429,MATCH('2'!B19,Daten!$A$7:$A$429,0)) -> 5.4197362e+09 | F19: =INDEX(Daten!$M$7:$M$429,MATCH('2'!B19,Daten!$A$7:$A$429,0)) -> 2.103907e+09 | G19: =INDEX(Daten!$N$7:$N$429,MATCH('2'!B19,Daten!$A$7:$A$429,0)) -> 1.6311256e+09 | H19: =INDEX(Daten!$P$7:$P$429,MATCH('2'!B19,Daten!$A$7:$A$429,0)) -> 6.895851e+08 | I19: =INDEX(Daten!$L$7:$L$429,MATCH('2'!B19,Daten!$A$7:$A$429,0)) -> 3.3759138e+08 | J19: =INDEX(Daten!$K$7:$K$429,MATCH('2'!B19,Daten!$A$7:$A$429,0)) -> 6.3524431e+08 | K19: =INDEX(Daten!$O$7:$O$429,MATCH('2'!B19,Daten!$A$7:$A$429,0)) -> 22282760 | L19: =INDEX(Daten!$Q$7:$Q$429,MATCH('2'!B19,Daten!$A$7:$A$429,0)) -> X
A20: =Daten!C13 -> Bremen | B20: =Daten!A13 -> 04 | C20: =Daten!F13 -> 04 | E20: =INDEX(Daten!$R$7:$R$429,MATCH('2'!B20,Daten!$A$7:$A$429,0)) -> 1.0017576e+09 | F20: =INDEX(Daten!$M$7:$M$429,MATCH('2'!B20,Daten!$A$7:$A$429,0)) -> 3.8674713e+08 | G20: =INDEX(Daten!$N$7:$N$429,MATCH('2'!B20,Daten!$A$7:$A$429,0)) -> 3.0300354e+08 | H20: =INDEX(Daten!$P$7:$P$429,MATCH('2'!B20,Daten!$A$7:$A$429,0)) -> 1.2249299e+08 | I20: =INDEX(Daten!$L$7:$L$429,MATCH('2'!B20,Daten!$A$7:$A$429,0)) -> 80920806 | J20: =INDEX(Daten!$K$7:$K$429,MATCH('2'!B20,Daten!$A$7:$A$429,0)) -> 1.032326e+08 | K20: =INDEX(Daten!$O$7:$O$429,MATCH('2'!B20,Daten!$A$7:$A$429,0)) -> 5360530.6 | L20: =INDEX(Daten!$Q$7:$Q$429,MATCH('2'!B20,Daten!$A$7:$A$429,0)) -> X
A21: =Daten!C14 -> Nordrhein-Westfalen | B21: =Daten!A14 -> 05 | C21: =Daten!F14 -> 05 | E21: =INDEX(Daten!$R$7:$R$429,MATCH('2'!B21,Daten!$A$7:$A$429,0)) -> 1.6301383e+10 | F21: =INDEX(Daten!$M$7:$M$429,MATCH('2'!B21,Daten!$A$7:$A$429,0)) -> 6.38929e+09 | G21: =INDEX(Daten!$N$7:$N$429,MATCH('2'!B21,Daten!$A$7:$A$429,0)) -> 4.8839967e+09 | H21: =INDEX(Daten!$P$7:$P$429,MATCH('2'!B21,Daten!$A$7:$A$429,0)) -> 2.0318916e+09 | I21: =INDEX(Daten!$L$7:$L$429,MATCH('2'!B21,Daten!$A$7:$A$429,0)) -> 1.1727391e+09 | J21: =INDEX(Daten!$K$7:$K$429,MATCH('2'!B21,Daten!$A$7:$A$429,0)) -> 1.7527622e+09 | K21: =INDEX(Daten!$O$7:$O$429,MATCH('2'!B21,Daten!$A$7:$A$429,0)) -> 70703407 | L21: =INDEX(Daten!$Q$7:$Q$429,MATCH('2'!B21,Daten!$A$7:$A$429,0)) -> X
A22: =Daten!C15 -> Hessen | B22: =Daten!A15 -> 06 | C22: =Daten!F15 -> 06 | E22: =INDEX(Daten!$R$7:$R$429,MATCH('2'!B22,Daten!$A$7:$A$429,0)) -> 4.2758934e+09 | F22: =INDEX(Daten!$M$7:$M$429,MATCH('2'!B22,Daten!$A$7:$A$429,0)) -> 1.6029478e+09 | G22: =INDEX(Daten!$N$7:$N$429,MATCH('2'!B22,Daten!$A$7:$A$429,0)) -> 1.419614e+09 | H22: =INDEX(Daten!$P$7:$P$429,MATCH('2'!B22,Daten!$A$7:$A$429,0)) -> 5.2769935e+08 | I22: =INDEX(Daten!$L$7:$L$429,MATCH('2'!B22,Daten!$A$7:$A$429,0)) -> 2.2169137e+08 | J22: =INDEX(Daten!$K$7:$K$429,MATCH('2'!B22,Daten!$A$7:$A$429,0)) -> 4.8154224e+08 | K22: =INDEX(Daten!$O$7:$O$429,MATCH('2'!B22,Daten!$A$7:$A$429,0)) -> 22398623 | L22: =INDEX(Daten!$Q$7:$Q$429,MATCH('2'!B22,Daten!$A$7:$A$429,0)) -> X
A23: =Daten!C16 -> Rheinland-Pfalz | B23: =Daten!A16 -> 07 | C23: =Daten!F16 -> 07 | E23: =INDEX(Daten!$R$7:$R$429,MATCH('2'!B23,Daten!$A$7:$A$429,0)) -> 2.214668e+09 | F23: =INDEX(Daten!$M$7:$M$429,MATCH('2'!B23,Daten!$A$7:$A$429,0)) -> 8.8660923e+08 | G23: =INDEX(Daten!$N$7:$N$429,MATCH('2'!B23,Daten!$A$7:$A$429,0)) -> 6.4972071e+08 | H23: =INDEX(Daten!$P$7:$P$429,MATCH('2'!B23,Daten!$A$7:$A$429,0)) -> 2.9025144e+08 | I23: =INDEX(Daten!$L$7:$L$429,MATCH('2'!B23,Daten!$A$7:$A$429,0)) -> 1.2340632e+08 | J23: =INDEX(Daten!$K$7:$K$429,MATCH('2'!B23,Daten!$A$7:$A$429,0)) -> 2.5658537e+08 | K23: =INDEX(Daten!$O$7:$O$429,MATCH('2'!B23,Daten!$A$7:$A$429,0)) -> 8094916.3 | L23: =INDEX(Daten!$Q$7:$Q$429,MATCH('2'!B23,Daten!$A$7:$A$429,0)) -> X
A24: =Daten!C17 -> Baden-Württemberg | B24: =Daten!A17 -> 08 | C24: =Daten!F17 -> 08 | E24: =INDEX(Daten!$R$7:$R$429,MATCH('2'!B24,Daten!$A$7:$A$429,0)) -> 5.0835535e+09 | F24: =INDEX(Daten!$M$7:$M$429,MATCH('2'!B24,Daten!$A$7:$A$429,0)) -> 1.9391078e+09 | G24: =INDEX(Daten!$N$7:$N$429,MATCH('2'!B24,Daten!$A$7:$A$429,0)) -> 1.6447576e+09 | H24: =INDEX(Daten!$P$7:$P$429,MATCH('2'!B24,Daten!$A$7:$A$429,0)) -> 6.3990268e+08 | I24: =INDEX(Daten!$L$7:$L$429,MATCH('2'!B24,Daten!$A$7:$A$429,0)) -> 2.9385662e+08 | J24: =INDEX(Daten!$K$7:$K$429,MATCH('2'!B24,Daten!$A$7:$A$429,0)) -> 5.4408124e+08 | K24: =INDEX(Daten!$O$7:$O$429,MATCH('2'!B24,Daten!$A$7:$A$429,0)) -> 21847516 | L24: =INDEX(Daten!$Q$7:$Q$429,MATCH('2'!B24,Daten!$A$7:$A$429,0)) -> X
A25: =Daten!C18 -> Bayern | B25: =Daten!A18 -> 09 | C25: =Daten!F18 -> 09 | E25: =INDEX(Daten!$R$7:$R$429,MATCH('2'!B25,Daten!$A$7:$A$429,0)) -> 4.574464e+09 | F25: =INDEX(Daten!$M$7:$M$429,MATCH('2'!B25,Daten!$A$7:$A$429,0)) -> 1.7753399e+09 | G25: =INDEX(Daten!$N$7:$N$429,MATCH('2'!B25,Daten!$A$7:$A$429,0)) -> 1.3935529e+09 | H25: =INDEX(Daten!$P$7:$P$429,MATCH('2'!B25,Daten!$A$7:$A$429,0)) -> 5.9508966e+08 | I25: =INDEX(Daten!$L$7:$L$429,MATCH('2'!B25,Daten!$A$7:$A$429,0)) -> 2.341262e+08 | J25: =INDEX(Daten!$K$7:$K$429,MATCH('2'!B25,Daten!$A$7:$A$429,0)) -> 5.5203433e+08 | K25: =INDEX(Daten!$O$7:$O$429,MATCH('2'!B25,Daten!$A$7:$A$429,0)) -> 24320913 | L25: =INDEX(Daten!$Q$7:$Q$429,MATCH('2'!B25,Daten!$A$7:$A$429,0)) -> X
... A32: =Daten!C25 -> Thüringen | B32: =Daten!A25 -> 16 | C32: =Daten!F25 -> 16 | E32: =INDEX(Daten!$R$7:$R$429,MATCH('2'!B32,Daten!$A$7:$A$429,0)) -> 1.1744005e+09 | F32: =INDEX(Daten!$M$7:$M$429,MATCH('2'!B32,Daten!$A$7:$A$429,0)) -> 4.8771278e+08 | G32: =INDEX(Daten!$N$7:$N$429,MATCH('2'!B32,Daten!$A$7:$A$429,0)) -> 2.957966e+08 | H32: =INDEX(Daten!$P$7:$P$429,MATCH('2'!B32,Daten!$A$7:$A$429,0)) -> 1.5744493e+08 | I32: =INDEX(Daten!$L$7:$L$429,MATCH('2'!B32,Daten!$A$7:$A$429,0)) -> 64205636 | J32: =INDEX(Daten!$K$7:$K$429,MATCH('2'!B32,Daten!$A$7:$A$429,0)) -> 1.6236192e+08 | K32: =INDEX(Daten!$O$7:$O$429,MATCH('2'!B32,Daten!$A$7:$A$429,0)) -> 6878601.8 | L32: =INDEX(Daten!$Q$7:$Q$429,MATCH('2'!B32,Daten!$A$7:$A$429,0)) -> X
A33: =Daten!C26 -> JC Vorpommern-Greifswald | B33: =Daten!A26 -> 03002 | C33: =Daten!F26 -> 13 | D33: =Daten!E26 -> IIId | E33: =INDEX(Daten!$R$7:$R$429,MATCH('2'!B33,Daten!$A$7:$A$429,0)) -> 1.8160685e+08 | F33: =INDEX(Daten!$M$7:$M$429,MATCH('2'!B33,Daten!$A$7:$A$429,0)) -> 73434908 | G33: =INDEX(Daten!$N$7:$N$429,MATCH('2'!B33,Daten!$A$7:$A$429,0)) -> 45391276 | H33: =INDEX(Daten!$P$7:$P$429,MATCH('2'!B33,Daten!$A$7:$A$429,0)) -> 23870983 | I33: =INDEX(Daten!$L$7:$L$429,MATCH('2'!B33,Daten!$A$7:$A$429,0)) -> 12585733 | J33: =INDEX(Daten!$K$7:$K$429,MATCH('2'!B33,Daten!$A$7:$A$429,0)) -> 25300148 | K33: =INDEX(Daten!$O$7:$O$429,MATCH('2'!B33,Daten!$A$7:$A$429,0)) -> 1023801.2 | L33: =INDEX(Daten!$Q$7:$Q$429,MATCH('2'!B33,Daten!$A$7:$A$429,0)) -> 2276910.6
A34: =Daten!C27 -> JC Mecklenburgische Seenplatte Süd | B34: =Daten!A27 -> 03102 | C34: =Daten!F27 -> 13 | D34: =Daten!E27 -> IIId | E34: =INDEX(Daten!$R$7:$R$429,MATCH('2'!B34,Daten!$A$7:$A$429,0)) -> 1.2304391e+08 | F34: =INDEX(Daten!$M$7:$M$429,MATCH('2'!B34,Daten!$A$7:$A$429,0)) -> 50412561 | G34: =INDEX(Daten!$N$7:$N$429,MATCH('2'!B34,Daten!$A$7:$A$429,0)) -> 31117423 | H34: =INDEX(Daten!$P$7:$P$429,MATCH('2'!B34,Daten!$A$7:$A$429,0)) -> 16241827 | I34: =INDEX(Daten!$L$7:$L$429,MATCH('2'!B34,Daten!$A$7:$A$429,0)) -> 7073905.6 | J34: =INDEX(Daten!$K$7:$K$429,MATCH('2'!B34,Daten!$A$7:$A$429,0)) -> 17339875 | K34: =INDEX(Daten!$O$7:$O$429,MATCH('2'!B34,Daten!$A$7:$A$429,0)) -> 858317.28 | L34: =INDEX(Daten!$Q$7:$Q$429,MATCH('2'!B34,Daten!$A$7:$A$429,0)) -> 1775195.9
A35: =Daten!C28 -> JC Mecklenburgische Seenplatte Nord | B35: =Daten!A28 -> 03122 | C35: =Daten!F28 -> 13 | D35: =Daten!E28 -> IIId | E35: =INDEX(Daten!$R$7:$R$429,MATCH('2'!B35,Daten!$A$7:$A$429,0)) -> 79598044 | F35: =INDEX(Daten!$M$7:$M$429,MATCH('2'!B35,Daten!$A$7:$A$429,0)) -> 32101052 | G35: =INDEX(Daten!$N$7:$N$429,MATCH('2'!B35,Daten!$A$7:$A$429,0)) -> 19767628 | H35: =INDEX(Daten!$P$7:$P$429,MATCH('2'!B35,Daten!$A$7:$A$429,0)) -> 10390224 | I35: =INDEX(Daten!$L$7:$L$429,MATCH('2'!B35,Daten!$A$7:$A$429,0)) -> 4007727 | J35: =INDEX(Daten!$K$7:$K$429,MATCH('2'!B35,Daten!$A$7:$A$429,0)) -> 12866847 | K35: =INDEX(Daten!$O$7:$O$429,MATCH('2'!B35,Daten!$A$7:$A$429,0)) -> 464567.08 | L35: =INDEX(Daten!$Q$7:$Q$429,MATCH('2'!B35,Daten!$A$7:$A$429,0)) -> 932499.98
A36: =Daten!C29 -> JC Rostock, Hansestadt | B36: =Daten!A29 -> 03202 | C36: =Daten!F29 -> 13 | D36: =Daten!E29 -> IIIe | E36: =INDEX(Daten!$R$7:$R$429,MATCH('2'!B36,Daten!$A$7:$A$429,0)) -> 1.6461302e+08 | F36: =INDEX(Daten!$M$7:$M$429,MATCH('2'!B36,Daten!$A$7:$A$429,0)) -> 64311827 | G36: =INDEX(Daten!$N$7:$N$429,MATCH('2'!B36,Daten!$A$7:$A$429,0)) -> 45230145 | H36: =INDEX(Daten!$P$7:$P$429,MATCH('2'!B36,Daten!$A$7:$A$429,0)) -> 21574233 | I36: =INDEX(Daten!$L$7:$L$429,MATCH('2'!B36,Daten!$A$7:$A$429,0)) -> 9931609.6 | J36: =INDEX(Daten!$K$7:$K$429,MATCH('2'!B36,Daten!$A$7:$A$429,0)) -> 22567061 | K36: =INDEX(Daten!$O$7:$O$429,MATCH('2'!B36,Daten!$A$7:$A$429,0)) -> 998142.2 | L36: =INDEX(Daten!$Q$7:$Q$429,MATCH('2'!B36,Daten!$A$7:$A$429,0)) -> 768130.98
A37: =Daten!C30 -> JC Landkreis Rostock | B37: =Daten!A30 -> 03208 | C37: =Daten!F30 -> 13 | D37: =Daten!E30 -> IIIa | E37: =INDEX(Daten!$R$7:$R$429,MATCH('2'!B37,Daten!$A$7:$A$429,0)) -> 1.18883e+08 | F37: =INDEX(Daten!$M$7:$M$429,MATCH('2'!B37,Daten!$A$7:$A$429,0)) -> 48224427 | G37: =INDEX(Daten!$N$7:$N$429,MATCH('2'!B37,Daten!$A$7:$A$429,0)) -> 31607849 | H37: =INDEX(Daten!$P$7:$P$429,MATCH('2'!B37,Daten!$A$7:$A$429,0)) -> 15334952 | I37: =INDEX(Daten!$L$7:$L$429,MATCH('2'!B37,Daten!$A$7:$A$429,0)) -> 8058731.3 | J37: =INDEX(Daten!$K$7:$K$429,MATCH('2'!B37,Daten!$A$7:$A$429,0)) -> 15117537 | K37: =INDEX(Daten!$O$7:$O$429,MATCH('2'!B37,Daten!$A$7:$A$429,0)) -> 539498.75 | L37: =INDEX(Daten!$Q$7:$Q$429,MATCH('2'!B37,Daten!$A$7:$A$429,0)) -> 1581754
A38: =Daten!C31 -> JC Schwerin, Landeshauptstadt | B38: =Daten!A31 -> 03302 | C38: =Daten!F31 -> 13 | D38: =Daten!E31 -> IIIe | E38: =INDEX(Daten!$R$7:$R$429,MATCH('2'!B38,Daten!$A$7:$A$429,0)) -> 1.0992199e+08 | F38: =INDEX(Daten!$M$7:$M$429,MATCH('2'!B38,Daten!$A$7:$A$429,0)) -> 44877132 | G38: =INDEX(Daten!$N$7:$N$429,MATCH('2'!B38,Daten!$A$7:$A$429,0)) -> 28679218 | H38: =INDEX(Daten!$P$7:$P$429,MATCH('2'!B38,Daten!$A$7:$A$429,0)) -> 14314467 | I38: =INDEX(Daten!$L$7:$L$429,MATCH('2'!B38,Daten!$A$7:$A$429,0)) -> 7746878.9 | J38: =INDEX(Daten!$K$7:$K$429,MATCH('2'!B38,Daten!$A$7:$A$429,0)) -> 13145604 | K38: =INDEX(Daten!$O$7:$O$429,MATCH('2'!B38,Daten!$A$7:$A$429,0)) -> 1158691.5 | L38: =INDEX(Daten!$Q$7:$Q$429,MATCH('2'!B38,Daten!$A$7:$A$429,0)) -> 1989494.8
A39: =Daten!C32 -> JC Nordwestmecklenburg | B39: =Daten!A32 -> 03304 | C39: =Daten!F32 -> 13 | D39: =Daten!E32 -> IIIa | E39: =INDEX(Daten!$R$7:$R$429,MATCH('2'!B39,Daten!$A$7:$A$429,0)) -> 89966541 | F39: =INDEX(Daten!$M$7:$M$429,MATCH('2'!B39,Daten!$A$7:$A$429,0)) -> 36695688 | G39: =INDEX(Daten!$N$7:$N$429,MATCH('2'!B39,Daten!$A$7:$A$429,0)) -> 22717096 | H39: =INDEX(Daten!$P$7:$P$429,MATCH('2'!B39,Daten!$A$7:$A$429,0)) -> 11957198 | I39: =INDEX(Daten!$L$7:$L$429,MATCH('2'!B39,Daten!$A$7:$A$429,0)) -> 5892383.4 | J39: =INDEX(Daten!$K$7:$K$429,MATCH('2'!B39,Daten!$A$7:$A$429,0)) -> 12398500 | K39: =INDEX(Daten!$O$7:$O$429,MATCH('2'!B39,Daten!$A$7:$A$429,0)) -> 305675.52 | L39: =INDEX(Daten!$Q$7:$Q$429,MATCH('2'!B39,Daten!$A$7:$A$429,0)) -> 407111.45
A40: =Daten!C33 -> JC Ludwigslust-Parchim | B40: =Daten!A33 -> 03324 | C40: =Daten!F33 -> 13 | D40: =Daten!E33 -> IIId | E40: =INDEX(Daten!$R$7:$R$429,MATCH('2'!B40,Daten!$A$7:$A$429,0)) -> 1.099409e+08 | F40: =INDEX(Daten!$M$7:$M$429,MATCH('2'!B40,Daten!$A$7:$A$429,0)) -> 46079781 | G40: =INDEX(Daten!$N$7:$N$429,MATCH('2'!B40,Daten!$A$7:$A$429,0)) -> 26435416 | H40: =INDEX(Daten!$P$7:$P$429,MATCH('2'!B40,Daten!$A$7:$A$429,0)) -> 14356149 | I40: =INDEX(Daten!$L$7:$L$429,MATCH('2'!B40,Daten!$A$7:$A$429,0)) -> 7394498.3 | J40: =INDEX(Daten!$K$7:$K$429,MATCH('2'!B40,Daten!$A$7:$A$429,0)) -> 14990419 | K40: =INDEX(Daten!$O$7:$O$429,MATCH('2'!B40,Daten!$A$7:$A$429,0)) -> 684633.98 | L40: =INDEX(Daten!$Q$7:$Q$429,MATCH('2'!B40,Daten!$A$7:$A$429,0)) -> 1553636.5
A41: =Daten!C34 -> JC Vorpommern-Rügen | B41: =Daten!A34 -> 03444 | C41: =Daten!F34 -> 13 | D41: =Daten!E34 -> IIId | E41: =INDEX(Daten!$R$7:$R$429,MATCH('2'!B41,Daten!$A$7:$A$429,0)) -> . | F41: =INDEX(Daten!$M$7:$M$429,MATCH('2'!B41,Daten!$A$7:$A$429,0)) -> 65200239 | G41: =INDEX(Daten!$N$7:$N$429,MATCH('2'!B41,Daten!$A$7:$A$429,0)) -> 43275418 | H41: =INDEX(Daten!$P$7:$P$429,MATCH('2'!B41,Daten!$A$7:$A$429,0)) -> 21515054 | I41: =INDEX(Daten!$L$7:$L$429,MATCH('2'!B41,Daten!$A$7:$A$429,0)) -> 11464732 | J41: =INDEX(Daten!$K$7:$K$429,MATCH('2'!B41,Daten!$A$7:$A$429,0)) -> . | K41: =INDEX(Daten!$O$7:$O$429,MATCH('2'!B41,Daten!$A$7:$A$429,0)) -> 1080477 | L41: =INDEX(Daten!$Q$7:$Q$429,MATCH('2'!B41,Daten!$A$7:$A$429,0)) -> 453355
A42: =Daten!C35 -> JC Cottbus, Stadt | B42: =Daten!A35 -> 03502 | C42: =Daten!F35 -> 12 | D42: =Daten!E35 -> IIIe | E42: =INDEX(Daten!$R$7:$R$429,MATCH('2'!B42,Daten!$A$7:$A$429,0)) -> 97580839 | F42: =INDEX(Daten!$M$7:$M$429,MATCH('2'!B42,Daten!$A$7:$A$429,0)) -> 39389676 | G42: =INDEX(Daten!$N$7:$N$429,MATCH('2'!B42,Daten!$A$7:$A$429,0)) -> 25056525 | H42: =INDEX(Daten!$P$7:$P$429,MATCH('2'!B42,Daten!$A$7:$A$429,0)) -> 12814034 | I42: =INDEX(Daten!$L$7:$L$429,MATCH('2'!B42,Daten!$A$7:$A$429,0)) -> 6904215.3 | J42: =INDEX(Daten!$K$7:$K$429,MATCH('2'!B42,Daten!$A$7:$A$429,0)) -> 12788882 | K42: =INDEX(Daten!$O$7:$O$429,MATCH('2'!B42,Daten!$A$7:$A$429,0)) -> 627507.56 | L42: =INDEX(Daten!$Q$7:$Q$429,MATCH('2'!B42,Daten!$A$7:$A$429,0)) -> 2041326.8
A43: =Daten!C36 -> JC Elbe-Elster | B43: =Daten!A36 -> 03504 | C43: =Daten!F36 -> 12 | D43: =Daten!E36 -> IIId | E43: =INDEX(Daten!$R$7:$R$429,MATCH('2'!B43,Daten!$A$7:$A$429,0)) -> 61148195 | F43: =INDEX(Daten!$M$7:$M$429,MATCH('2'!B43,Daten!$A$7:$A$429,0)) -> 24732204 | G43: =INDEX(Daten!$N$7:$N$429,MATCH('2'!B43,Daten!$A$7:$A$429,0)) -> 15742993 | H43: =INDEX(Daten!$P$7:$P$429,MATCH('2'!B43,Daten!$A$7:$A$429,0)) -> 7964689.6 | I43: =INDEX(Daten!$L$7:$L$429,MATCH('2'!B43,Daten!$A$7:$A$429,0)) -> 3608379.7 | J43: =INDEX(Daten!$K$7:$K$429,MATCH('2'!B43,Daten!$A$7:$A$429,0)) -> 8779904.7 | K43: =INDEX(Daten!$O$7:$O$429,MATCH('2'!B43,Daten!$A$7:$A$429,0)) -> 320022.77 | L43: =INDEX(Daten!$Q$7:$Q$429,MATCH('2'!B43,Daten!$A$7:$A$429,0)) -> 560948.77
A44: =Daten!C37 -> JC Oberspreewald-Lausitz | B44: =Daten!A37 -> 03506 | C44: =Daten!F37 -> 12 | D44: =Daten!E37 -> IIId | E44: =INDEX(Daten!$R$7:$R$429,MATCH('2'!B44,Daten!$A$7:$A$429,0)) -> 75843103 | F44: =INDEX(Daten!$M$7:$M$429,MATCH('2'!B44,Daten!$A$7:$A$429,0)) -> 30504896 | G44: =INDEX(Daten!$N$7:$N$429,MATCH('2'!B44,Daten!$A$7:$A$429,0)) -> 19540024 | H44: =INDEX(Daten!$P$7:$P$429,MATCH('2'!B44,Daten!$A$7:$A$429,0)) -> 9912761.2 | I44: =INDEX(Daten!$L$7:$L$429,MATCH('2'!B44,Daten!$A$7:$A$429,0)) -> 4200927.2 | J44: =INDEX(Daten!$K$7:$K$429,MATCH('2'!B44,Daten!$A$7:$A$429,0)) -> 11431408 | K44: =INDEX(Daten!$O$7:$O$429,MATCH('2'!B44,Daten!$A$7:$A$429,0)) -> 253086.55 | L44: =INDEX(Daten!$Q$7:$Q$429,MATCH('2'!B44,Daten!$A$7:$A$429,0)) -> 749214.95
... A436: =Daten!C429 -> JC Lichtenberg | B436: =Daten!A429 -> 96208 | C436: =Daten!F429 -> 11 | D436: =Daten!E429 -> IIIb | E436: =INDEX(Daten!$R$7:$R$429,MATCH('2'!B436,Daten!$A$7:$A$429,0)) -> 4.0357338e+08 | F436: =INDEX(Daten!$M$7:$M$429,MATCH('2'!B436,Daten!$A$7:$A$429,0)) -> 1.5061464e+08 | G436: =INDEX(Daten!$N$7:$N$429,MATCH('2'!B436,Daten!$A$7:$A$429,0)) -> 1.3157757e+08 | H436: =INDEX(Daten!$P$7:$P$429,MATCH('2'!B436,Daten!$A$7:$A$429,0)) -> 48913571 | I436: =INDEX(Daten!$L$7:$L$429,MATCH('2'!B436,Daten!$A$7:$A$429,0)) -> 28424274 | J436: =INDEX(Daten!$K$7:$K$429,MATCH('2'!B436,Daten!$A$7:$A$429,0)) -> 42338486 | K436: =INDEX(Daten!$O$7:$O$429,MATCH('2'!B436,Daten!$A$7:$A$429,0)) -> 1704835.4 | L436: =INDEX(Daten!$Q$7:$Q$429,MATCH('2'!B436,Daten!$A$7:$A$429,0)) -> 2131743.5
L437: © Statistik der Bundesagentur für Arbeit
A439: =Steuerung_Eckwerte!I10 -> ¹ Umfasst alle Eingliederungsleistungen nach § 16 ff. SGB II (ohne kommunale Eingliederungsleistungen gem. § 16a SGB II), die durch den Bund erstattungsfähig sind. Die Kosten für die Eignungsfeststellung nach § 16 SGB II in Verbindung mit § 32 SGB III können sowohl über das Verwaltungsbudget als auch als Eingliederungsleistung abgerechnet werden.
A440: =Steuerung_Eckwerte!I11 -> ² Die Ausgaben für überörtliche Verwaltungsaufgaben der BA sowie für sonstige überörtlich wahrzunehmende Aufgaben der BA (z.B. SGB II-Statistik) und Sonderbedarfe (z.B. für Organisationsänderungen gemäß § 6a Absatz 7 SGB II und für die Umsetzung der Bundesprogramme) sind nicht enthalten.
A441: =Steuerung_Eckwerte!I12 -> ³ Die Verwaltungsausgaben beinhalten nicht den kommunalen Finanzierungsanteil.
...

Sheet 3
I1: Ausgaben im SGB II
A3: Tabelle 3: Eckwerte der Grundsicherung im SGB II | H3: zurück zum Inhalt
A4: Deutschland, West/Ost und Jobcenter (Gebietsstand Dezember 2024)
A5: Jahresdurchschnitt 2024
E7: Bedarfs- gemein- schaften (BG) | F7: Personen in Bedarfs- gemein- schaften (PERS) | G7: dar. (Sp. 2)
A8: Region | B8: Tr Nr | C8: Bundes- land | D8: Ver- gleichs- typ | G8: Regel- leistungs- berechtigte (RLB) | H8: dav. (Sp. 3)
H9: Erwerbsfähige Leistungs- berechtigte (ELB) | I9: Nicht erwerbsfähige Leistungs- berechtigte (NEF)
E10: 1 | F10: 2 | G10: 3 | H10: 4 | I10: 5
A11: Deutschland | B11: D | C11: D | E11: 2931462.9 | F11: 5766789.8 | G11: 5501028.3 | H11: 3987699.6 | I11: 1513328.7
A12: Westdeutschland | B12: W | C12: W | E12: 2220341.9 | F12: 4460279.8 | G12: 4262943.6 | H12: 3061166.3 | I12: 1201777.2
A13: Ostdeutschland | B13: O | C13: O | E13: 711121 | F13: 1306510 | G13: 1238084.7 | H13: 926533.25 | I13: 311551.42
A14: JC Vorpommern-Greifswald | B14: 03002 | C14: 13 | D14: IIId | E14: 10592.583 | F14: 18498.5 | G14: 17111.833 | H14: 13370.917 | I14: 3740.9167
A15: JC Mecklenburgische Seenplatte Süd | B15: 03102 | C15: 13 | D15: IIId | E15: 7214.9167 | F15: 12801 | G15: 11941.5 | H15: 9079.5 | I15: 2862
A16: JC Mecklenburgische Seenplatte Nord | B16: 03122 | C16: 13 | D16: IIId | E16: 4790.75 | F16: 8188.5 | G16: 7491.5833 | H16: 5845.3333 | I16: 1646.25
A17: JC Rostock, Hansestadt | B17: 03202 | C17: 13 | D17: IIIe | E17: 9801.5833 | F17: 16261.083 | G17: 15243.667 | H17: 11928.5 | I17: 3315.1667
A18: JC Landkreis Rostock | B18: 03208 | C18: 13 | D18: IIIa | E18: 6813.75 | F18: 12325.667 | G18: 11432.25 | H18: 8659.0833 | I18: 2773.1667
A19: JC Schwerin, Landeshauptstadt | B19: 03302 | C19: 13 | D19: IIIe | E19: 6133.5833 | F19: 11336.25 | G19: 10687.75 | H19: 7975.5833 | I19: 2712.1667
A20: JC Nordwestmecklenburg | B20: 03304 | C20: 13 | D20: IIIa | E20: 5266.3333 | F20: 9373.1667 | G20: 8650.75 | H20: 6661.5833 | I20: 1989.1667
A21: JC Ludwigslust-Parchim | B21: 03324 | C21: 13 | D21: IIId | E21: 6332 | F21: 11712.5 | G21: 10792.917 | H21: 8074.3333 | I21: 2718.5833
A22: JC Vorpommern-Rügen | B22: 03444 | C22: 13 | D22: IIId | E22: 9495.0833 | F22: 16003.5 | G22: 15395.75 | H22: 11828.25 | I22: 3567.5
A23: JC Cottbus, Stadt | B23: 03502 | C23: 12 | D23: IIIe | E23: 5610.1667 | F23: 10229.5 | G23: 9652.0833 | H23: 7171.0833 | I23: 2481
A24: JC Elbe-Elster | B24: 03504 | C24: 12 | D24: IIId | E24: 3612 | F24: 6237.4167 | G24: 5849.1667 | H24: 4476.6667 | I24: 1372.5
A25: JC Oberspreewald-Lausitz | B25: 03506 | C25: 12 | D25: IIId | E25: 4491.75 | F25: 7801.4167 | G25: 7284.0833 | H25: 5624.8333 | I25: 1659.25
... A417: JC Lichtenberg | B417: 96208 | C417: 11 | D417: IIIb | E417: 20397.25 | F417: 40107.75 | G417: 38002 | H417: 27009 | I417: 10993
I418: © Statistik der Bundesagentur für Arbeit

Sheet 4
I1: Ausgaben im SGB II
H3: zurück zum Inhalt
A6: Die Statistik der Bundesagentur für Arbeit berichtet seit 2005 im Rahmen der Grundsicherungsstatistik über passive Leistungen zum Lebensunterhalt aus dem SGB II an Bedarfsgemeinschaften und Personen. Diese Zahlungsansprüche finden grundsätzlich als Summen ihre Entsprechung in den Ausgaben eines Trägers. Die Summe der Zahlungsansprüche aus der Leistungsstatistik SGB II und die Ausgabensummen aus den Haushaltsdaten der Träger sind allerdings aufgrund von mess- und zähltechnischen Unterschieden nicht identisch:
A12: Bestandskonzept versus Zahlungsfluss: Während die Leistungsstatistik SGB II ausschließlich Zahlungsansprüche von Bedarfsgemeinschaften summiert, die zum statistischen Stichtag (Mitte des Monats) bestandsrelevant waren, bezieht die Ausgabensumme in der Regel alle Ausgaben eines Zeitraums ein, also auch für BG, die nicht bestandsrelevant waren.
A16: Zeitliche Zuordnung: Die Leistungsstatistik SGB II ordnet Zahlungsansprüche dem Bedarfsmonat zu, während sich die Zählung von Ausgaben in der Regel am Zeitpunkt des Geldflusses orientiert. Nachzahlungen für mehrere nachbewilligte Leistungsmonate werden somit bei den Ausgaben im Zahlmonat als Summe ausgewiesen, in der Leistungsstatistik SGB II im jeweiligen Bedarfsmonat.
A21: Wartezeitkonzept: Ergebnisse der Leistungsstatistik SGB II werden mit einer Wartezeit von 3 Monaten festgeschrieben, während zahlungsrelevante Änderungen in der Regel in der Ausgabensumme am aktuellen Rand aufgeführt werden.
A24: In diesem Produkt „Ausgaben im SGB II“ werden zum Vergleich und zur besseren Einschätzbarkeit hier die Summen der Zahlungsansprüche aus der Statistik über passive Leistungen aus dem SGB II des Jahres 2024 dargestellt. Die Aggregation der Zahlungsansprüche erfolgt spiegelbildlich zu den Kategorien der Ausgaben in Tabelle 1 und 2. Dies weicht geringfügig von den Darstellungen der Grundsicherungsstatistik SGB II ab.
A30: Tabelle 4: Zahlungsanspüche im SGB II
A31: Deutschland, West/Ost und Jobcenter (Gebietsstand Dezember 2024)
A32: Jahressumme 2024
E34: Zahlungs- ansprüche insgesamt 1) | F34: dav. (Sp. 1)
A35: Region | B35: Tr Nr | C35: Bundes- land | D35: Ver- gleichs- typ | F35: Regelbedarfe, Mehrbedarfe, unabweisbarer Bedarf 2) | G35: Kosten der Unterkunft | H35: Abweichend zu erbringende Leistungen | I35: Zahlungs- ansprüche für Leistungen zur Sozialver- sicherung
E36: 1 | F36: 2 | G36: 3 | H36: 4 | I36: 5
A37: Deutschland | B37: D | C37: D | E37: 4.6920954e+10 | F37: 2.193585e+10 | G37: 1.768482e+10 | H37: 2.4845281e+08 | I37: 7.0518316e+09
A38: Westdeutschland | B38: W | C38: W | E38: 3.6184795e+10 | F38: 1.6797852e+10 | G38: 1.37959e+10 | H38: 1.8368462e+08 | I38: 5.4073584e+09
A39: Ostdeutschland | B39: O | C39: O | E39: 1.0736159e+10 | F39: 5.1379983e+09 | G39: 3.8889196e+09 | H39: 64768195 | I39: 1.6444732e+09
A40: JC Vorpommern-Greifswald | B40: 03002 | C40: 13 | D40: IIId | E40: 1.452531e+08 | F40: 74189227 | G40: 46423786 | H40: 1001849.9 | I40: 23638239
A41: JC Mecklenburgische Seenplatte Süd | B41: 03102 | C41: 13 | D41: IIId | E41: 1.0030426e+08 | F41: 51265385 | G41: 32136476 | H41: 854553.71 | I41: 16047842
A42: JC Mecklenburgische Seenplatte Nord | B42: 03122 | C42: 13 | D42: IIId | E42: 63515545 | F42: 32389462 | G42: 20327316 | H42: 446990.57 | I42: 10351777
A43: JC Rostock, Hansestadt | B43: 03202 | C43: 13 | D43: IIIe | E43: 1.3424367e+08 | F43: 64788606 | G43: 47259061 | H43: 1001938.6 | I43: 21194067
A44: JC Landkreis Rostock | B44: 03208 | C44: 13 | D44: IIIa | E44: 97084661 | F44: 48587121 | G44: 32604769 | H44: 533898.91 | I44: 15358873
A45: JC Schwerin, Landeshauptstadt | B45: 03302 | C45: 13 | D45: IIIe | E45: 90056215 | F45: 45091532 | G45: 29702184 | H45: 1103623.8 | I45: 14158874
A46: JC Nordwestmecklenburg | B46: 03304 | C46: 13 | D46: IIIa | E46: 72362094 | F46: 36811334 | G46: 23416023 | H46: 308350.15 | I46: 11826388
A47: JC Ludwigslust-Parchim | B47: 03324 | C47: 13 | D47: IIId | E47: 88067139 | F47: 46000691 | G47: 27065277 | H47: 689037.55 | I47: 14312133
A48: JC Vorpommern-Rügen | B48: 03444 | C48: 13 | D48: IIId | E48: 1.3206601e+08 | F48: 65970221 | G48: 44225289 | H48: 1058330.1 | I48: 20812173
A49: JC Cottbus, Stadt | B49: 03502 | C49: 12 | D49: IIIe | E49: 78949912 | F49: 39730773 | G49: 25901782 | H49: 620035.86 | I49: 12697322
A50: JC Elbe-Elster | B50: 03504 | C50: 12 | D50: IIId | E50: 49674009 | F50: 25304002 | G50: 16109114 | H50: 324719 | I50: 7936174.2
A51: JC Oberspreewald-Lausitz | B51: 03506 | C51: 12 | D51: IIId | E51: 61371264 | F51: 31054492 | G51: 20121609 | H51: 245617.28 | I51: 9949545.5
... A239: JC Gießen | B239: 42702 | C239: 06 | D239: IId | E239: 1.9146704e+08 | F239: 86449961 | G239: 75592962 | H239: 1557037 | I239: 27867083
A240: JC Vogelsbergkreis | B240: 42704 | C240: 06 | D240: IIa | E240: 0 | F240: . | G240: . | H240: . | I240: .
A241: JC Wetteraukreis | B241: 42708 | C241: 06 | D241: IId | E241: 1.3112992e+08 | F241: 60021983 | G241: 50685525 | H241: 658542.82 | I241: 19763872
A242: JC Main-Kinzig-Kreis | B242: 43102 | C242: 06 | D242: IId | E242: 2.3346195e+08 | F242: 1.0796667e+08 | G242: 90504852 | H242: 1788797.2 | I242: 33201630
A243: JC Hochtaunuskreis | B243: 43302 | C243: 06 | D243: IIe | E243: 96386024 | F243: 44375467 | G243: 37783612 | H243: 397964.22 | I243: 13828981
A244: JC Main-Taunus-Kreis | B244: 43304 | C244: 06 | D244: IIe | E244: 1.1045728e+08 | F244: 45805874 | G244: 49483983 | H244: 478281.67 | I244: 14689137
A245: JC Groß-Gerau | B245: 43306 | C245: 06 | D245: IIe | E245: 1.719624e+08 | F245: 74888177 | G245: 71416204 | H245: 718763.12 | I245: 24939253
A246: JC Kassel, documenta-Stadt | B246: 43502 | C246: 06 | D246: IIIb | E246: 1.9696943e+08 | F246: 92254498 | G246: 73691153 | H246: 1129453.7 | I246: 29894324
A247: JC Kassel | B247: 43504 | C247: 06 | D247: IId | E247: 93418382 | F247: 45694218 | G247: 33100839 | H247: 463175.27 | I247: 14160150
A248: JC Werra-Meißner-Kreis | B248: 43520 | C248: 06 | D248: IIa | E248: 44629222 | F248: 22754306 | G248: 14386126 | H248: 366404.32 | I248: 7122386.2
A249: JC Waldeck-Frankenberg | B249: 43902 | C249: 06 | D249: Ie | E249: 62045252 | F249: 30580989 | G249: 21685191 | H249: 416597.05 | I249: 9362474.8
A250: JC Schwalm-Eder-Kreis | B250: 43904 | C250: 06 | D250: IIa | E250: 67472577 | F250: 34258732 | G250: 22099486 | H250: 563194.53 | I250: 10551164
...

Sheet Methodische Hinweise
H1: Ausgaben im SGB II
H2: Stand: 17.11.2025
A4: Methodische Hinweise | G4: zurück zum Inhalt
A5: Ausgaben für aktive und passive Leistungen im SGB II 2024
A8: Abkürzungen
A10: . | B10: Fehlende Werte bei einzelnen Trägern können wegen unplausibler beziehungsweise unvollständiger Datenlage auftreten.
A11: X | B11: Nachweis ist nicht sinnvoll
A12: .X | B12: Veränderungswert >250% bzw. Veränderungswert <-250%
A14: Allgemeine Hinweise
A16: Die Ausgaben für aktive und passive Leistungen sind die tatsächlich erbrachten Zahlungen der Jobcenter. Das heißt, dass Rückeinnahmen den Ausgaben zufließen. Dies können zum Beispiel zu viel geleistete Ausgaben (Rückzahlung aufgrund der Unrechtmäßigkeit einer Zahlung, zum Beispiel Doppelzahlung, Überzahlung) sein.
A18: Gebietsstand
A20: Die Daten beziehen sich auf den Gebietsstand zum Dezember 2024.
A22: Datenquellen
A24: Für Jobcenter in gemeinsamer Einrichtung:
A26: Finanzsysteme der Bundesagentur für Arbeit (BA)
A28: Die Daten für Deutschland beinhalten die Buchungen der Jobcenter zuzüglich der Buchungen der Regionaldirektionen, der besonderen Dienststellen und SGB III-Dienststellen (BA) auf Finanzpositionen des SGB II.
A30: Die Daten für Ost- und Westdeutschland sowie der Bundesländer beinhalten die Buchungen der Jobcenter zuzüglich der Buchungen der SGB III-Dienststellen (BA) auf Finanzpositionen des SGB II. Buchungen der besonderen Dienststellen sowie der Regionaldirektionen sind nicht enthalten.
A32: Für Jobcenter in zugelassener kommunaler Trägerschaft:
A34: Datenstandard XSozial-BA-SGB II
A36: Aktuelle Version unter:
... A53: http://doku.iab.de/forschungsbericht/2013/fb1113.pdf

Sheet Glossar
H1: Ausgaben im SGB II
H2: Stand: 17.11.2025
A4: Glossar | G4: zurück zum Inhalt
A5: Ausgaben für aktive und passive Leistungen im SGB II 2024
A6: Seite 1/3
A8: Bürgergeld (Bundesleistung)
A10: Bürgergeld ist die Gesamtregelleistung zur Sicherung des Lebensunterhalts nach dem SGB II. Man unterscheidet zwischen Bürgergeld für erwerbsfähige Leistungsberechtigte nach § 19 Absatz 1 Satz 1 SGB II (Bürgergeld für ELB, vor 2023: Arbeitslosengeld II) und Bürgergeld für nicht erwerbsfähige Leistungsberechtigte nach § 19 Absatz 1 Satz 2 SGB II (Bürgergeld für NEF, vor 2023: Sozialgeld).
A12: Die Ausgaben für Bürgergeld (ohne Kosten der Unterkunft) beinhalten folgende Bundesleistungen:
B14: ■ Regelbedarf nach § 20 SGB II
B15: ■ Befristeter Zuschlag nach dem Bezug von Arbeitslosengeld (Rechtsgrundlage entfallen zum 01.01.2011)
B16: ■ Darlehensweise Geldleistungen bzw. Anschaffung von Sachleistungen nach § 24 Abs. 1 SGB II
B17: ■ Leistungen für Mehrbedarfe beim Lebensunterhalt für werdende Mütter nach § 21 Abs. 2 SGB II
B18: ■ Leistungen für Mehrbedarfe beim Lebensunterhalt für Alleinerziehende nach § 21 Abs. 3 SGB II
B19: ■ Leistungen für Mehrbedarfe beim Lebensunterhalt für erwerbsfähige Leistungsberechtigte mit Behinderung nach § 21 Abs. 4 SGB II
B20: ■ Leistungen für Mehrbedarfe beim Lebensunterhalt für nicht erwerbsfähige Leistungsberechtigte mit Behinderung nach §19 Abs. 1 S. 2 i.V.m. §23 Nr.2 SGB II
B21: ■ Leistungen für Mehrbedarfe beim Lebensunterhalt für kostenaufwändige Ernährung nach § 21 Abs. 5 SGB II
B22: ■ Unabweisbare besondere Bedarfe, die in atypischen Lebenslagen anfallen nach § 21 Abs. 6 SGB II
B23: ■ Leistungen für Mehrbedarfe - Energie und Warmwasser nach § 21 Abs. 7 SGB II
B24: ■ Leistungen für Mehrbedarfe - Schulbuchförderung nach § 21 Abs. 6a SGB II
B25: ■ Einmalzahlung aus Anlass der COVID-19-Pandemie nach § 70, 73 SGB II
... B28: ■ Teilhabe am Arbeitsmarkt § 16i SGB II - Zuschuss zum Arbeitsentgelt
A30: Die Zahlungsrückläufe und Rückeinnahmen aus dem Forderungseinzug von Bundesleistungen in den Finanzsystemen der BA aus früheren Jahren werden vom Bürgergeld abgezogen. Die Buchungssummen belaufen sich im Jahr 2024 bundesweit auf 3.001.302,47.
A32: Nicht berücksichtigt werden die Zuschüsse zu orthopädischen Schuhen, therapeutischen Geräten, Ausrüstungen sowie Miete von therapeutischen Ausrüstungen. In den Finanzsystemen der BA wurden im Jahr 2024 insgesamt 81.295,43 Euro erfasst.
A35: Kosten der Unterkunft
A37: Unter den Kosten der Unterkunft werden folgende Ausgaben zusammengefasst:
B39: ■ Leistungen für Unterkunft und Heizung
B40: ■ Wohnungsbeschaffungskosten, Mietkaution, Umzugskosten
B41: ■ Übernahme der Mietschulden
B42: ■ Zuschuss zu den Leistungen für Unterkunft und Heizung bei ausgeschlossenen Auszubildenden
B43: ■ Zuschuss zu Genossenschaftsanteilen
B44: ■ Zuschuss Instandhaltung und Reparatur bei selbstgenutztem Wohneigentum
B45: ■ Darlehensweise Übernahme der Leistungen für Unterkunft und Heizung
B46: ■ Darlehensweise Übernahme der Wohnungsbeschaffungskosten, Mietkaution, Umzugskosten
B47: ■ Darlehensweise Übernahme der Mietschulden
B48: ■ Darlehensweise Übernahme des Zuschusses zu den Leistungen für Unterkunft und Heizung bei ausgeschlossenen Auszubildenden
B49: ■ Darlehensweise Übernahme von Genossenschaftsanteilen
B50: ■ Darlehen Instandhaltung und Reparatur bei selbstgenutzem Wohneigentum
... B56: ■ Tilgungen der darlehensweisen Übernahme von Instandhaltung und Reparatur von selbstgenutzem Wohneigentum
A59: Leistungen zur Sozialversicherung
A61: Bei den Leistungen zur Sozialversicherung handelt es sich um folgende Leistungen:
...

Sheet Statistik-Infoseite
G2: Stand: 11.04.2025
A3: Statistik-Infoseite
A6: Im Internet stehen statistische Informationen zu diesen Themen zur Verfügung:
B8: Fachstatistiken:
B9: Arbeitsuche, Arbeitslosigkeit und Unterbeschäftigung
B10: Ausbildungsmarkt
B11: Beschäftigung
B12: Einnahmen/Ausgaben
B13: Förderung und berufliche Rehabilitation
B14: Gemeldete Arbeitsstellen
B15: Grundsicherung für Arbeitsuchende (SGB II)
B16: Leistungen SGB III
B18: Themen im Fokus:
B19: Berufe
B20: Bildung
... B26: Frauen und Männer
A27: Jüngere | B27: Jüngere
B28: Langzeitarbeitslosigkeit
B29: Menschen mit Behinderungen
B30: Migration
B31: Regionale Mobilität
B32: Transformation
B33: Ukraine-Krieg
B34: Wirtschaftszweige
B35: Zeitarbeit
A37: Die Methodischen Hinweise der Statistik bieten ergänzende Informationen.
A39: Die Qualitätsberichte der Statistik erläutern die Entstehung und Aussagekraft der jeweiligen Fachstatistik.
A41: Das Glossar enthält Erläuterungen zu allen statistisch relevanten Begriffen, die in den verschiedenen Produkten der Statistik der BA Verwendung finden.
A44: Abkürzungen und Zeichen, die in den Produkten der Statistik der BA vorkommen, werden im
A45: Abkürzungsverzeichnis | C45: bzw. der Zeichenerklärung der Statistik der BA erläutert.

Sheet Steuerung_Eckwerte
A1: Region für die Auswahlliste (ohne Gebietsstand) (Trägernummer und Trägerbezeichnung im gelben Bereich sind zu aktualisieren) | C1: Region für die Tabellenüberschrift (Formeln im grünen Bereich müssen i.d.R. nicht angepasst werden) | D1: Gebietsstand | E1: Hinweise über der Tabelle | F1: Fußnote in der Regionen- bezeichnung (Formeln im grünen Bereich müssen i.d.R. nicht angepasst werden) | H1: Hinweise und Fußnoten (Text und Nummerierung hier anpassen)
B3: =INDEX(B6:B428,C4) -> Deutschland | C3: =INDEX(C6:C428,C4) -> Deutschland | D3: (Gebietsstand Dezember 2024) | E3: =INDEX(E6:E428,C4) -> H1 | F3: =INDEX(F6:F428,C4) -> 0 | H3: Hinweise über der Tabelle
C4: 1 | H4: H1 | I4: Die Daten für Deutschland insgesamt beinhalten die Buchungen der Jobcenter zuzüglich der Buchungen der Regionaldirektionen, der besonderen Dienststellen und SGB III-Dienststellen (BA) auf Finanzpositionen des SGB II.
H5: H2 | I5: Die Daten für Ost- und Westdeutschland sowie der Bundesländer beinhalten die Buchungen der Jobcenter zuzüglich der Buchungen der SGB III-Dienststellen (BA) auf Finanzpositionen des SGB II. Buchungen der besonderen Dienststellen sowie der Regionaldirektionen sind nicht enthalten.
A6: D | B6: Deutschland | C6: Deutschland | E6: H1 | H6: H3 | I6: Mit Ausnahme der Ausgaben für Bildung und Teilhabe wurden die Informationen für Deutschland, Ost- und Westdeutschland sowie die Bundesländer um die unplausiblen bzw. nicht vorhandenen Daten einzelner Jobcenter hochgerechnet. Für unplausible bzw. unvollständige Datenlieferungen im Bereich Eingliederungsleistungen wird bereits auf Jobcenter-Ebene ein Schätzwert gebildet.
A7: W | B7: Westdeutschland | C7: Westdeutschland | E7: H2
A8: O | B8: Ostdeutschland | C8: Ostdeutschland | E8: H2
A9: 01 | B9: Schleswig-Holstein | C9: Schleswig-Holstein | E9: H2 | H9: Fußnoten unter der Tabelle
A10: 02 | B10: Hamburg | C10: Hamburg | E10: H2 | H10: ¹ | I10: ¹ Umfasst alle Eingliederungsleistungen nach § 16 ff. SGB II (ohne kommunale Eingliederungsleistungen gem. § 16a SGB II), die durch den Bund erstattungsfähig sind. Die Kosten für die Eignungsfeststellung nach § 16 SGB II in Verbindung mit § 32 SGB III können sowohl über das Verwaltungsbudget als auch als Eingliederungsleistung abgerechnet werden.
A11: 03 | B11: Niedersachsen | C11: Niedersachsen | E11: H2 | H11: ² | I11: ² Die Ausgaben für überörtliche Verwaltungsaufgaben der BA sowie für sonstige überörtlich wahrzunehmende Aufgaben der BA (z.B. SGB II-Statistik) und Sonderbedarfe (z.B. für Organisationsänderungen gemäß § 6a Absatz 7 SGB II und für die Umsetzung der Bundesprogramme) sind nicht enthalten.
A12: 04 | B12: Bremen | C12: Bremen | E12: H2 | H12: ³ | I12: ³ Die Verwaltungsausgaben beinhalten nicht den kommunalen Finanzierungsanteil.
A13: 05 | B13: Nordrhein-Westfalen | C13: Nordrhein-Westfalen | E13: H2 | H13: ⁴ | I13: ⁴ Für die Leistungen für Bildung und Teilhabe nach § 28 SGB II besteht noch keine vollständige Datenübermittlung. Aus diesem Grund werden die Ausgaben für Bildung und Teilhabe nur nachrichtlich für die einzelnen Jobcenter berichtet und fließen daher auch nicht in die Insgesamtsumme ein. Es werden keine Summen für Deutschland, Westdeutschland, Ostdeutschland und für die Bundesländer gebildet. Ein Vorjahresvergleich ist nur eingeschränkt möglich.
A14: 06 | B14: Hessen | C14: Hessen | E14: H2 | H14: ⁵ | I14: ⁵ Aufgrund von Änderungen in der Regionalzuordnung von Gemeinden zu Jobcentern ist ein Vergleich mit dem Vorjahr nur eingeschränkt möglich.
A15: 07 | B15: Rheinland-Pfalz | C15: Rheinland-Pfalz | E15: H2
A16: 08 | B16: Baden-Württemberg | C16: Baden-Württemberg | E16: H2
A17: 09 | B17: Bayern | C17: Bayern | E17: H2
A18: 10 | B18: Saarland | C18: Saarland | E18: H2
A19: 11 | B19: Berlin | C19: Berlin | E19: H2
A20: 12 | B20: Brandenburg | C20: Brandenburg | E20: H2 | H20: Nicht verwendete Standard-Fußnoten
A21: 13 | B21: Mecklenburg-Vorpommern | C21: Mecklenburg-Vorpommern | E21: H2
A22: 14 | B22: Sachsen | C22: Sachsen | E22: H2 | H22: ⁷ | I22: ⁷ Aufgrund einer Mischkreisfusion mit neuer Trägerschaft gE und der damit verbundenen teilweisen Umstellungsprozesse in der Datenübermittlung ist der Vorjahresvergleich der Ausgaben eingeschränkt.
A23: 15 | B23: Sachsen-Anhalt | C23: Sachsen-Anhalt | E23: H2 | H23: ⁶ | I23: ⁶ Trägerfusion: Die Daten beziehen sich auf den Gebietsstand zum Dezember 2022. Die Daten für das Jahr 2021 wurden auf den neuen Gebietsstand umgerechnet.
A24: 16 | B24: Thüringen | C24: Thüringen | E24: H2
A25: 51906 | B25: JC Ahrweiler | C25: =CONCATENATE(B25, " ", $D$3, " ", F25) -> JC Ahrweiler (Gebietsstand Dezember 2024) | F25: =IF(INDEX(Daten!$H$26:$H$429,MATCH(Steuerung_Eckwerte!B25,Daten!$C$26:$C$429,0))=0, " ", INDEX(Daten!$H$26:$H$429,MATCH(Steuerung_Eckwerte!B25,Daten!$C$26:$C$429,0)))
A26: 81102 | B26: JC Aichach-Friedberg | C26: =CONCATENATE(B26, " ", $D$3, " ", F26) -> JC Aichach-Friedberg (Gebietsstand Dezember 2024) | F26: =IF(INDEX(Daten!$H$26:$H$429,MATCH(Steuerung_Eckwerte!B26,Daten!$C$26:$C$429,0))=0, " ", INDEX(Daten!$H$26:$H$429,MATCH(Steuerung_Eckwerte!B26,Daten!$C$26:$C$429,0)))
A27: 68404 | B27: JC Alb-Donau-Kreis | C27: =CONCATENATE(B27, " ", $D$3, " ", F27) -> JC Alb-Donau-Kreis (Gebietsstand Dezember 2024) | F27: =IF(INDEX(Daten!$H$26:$H$429,MATCH(Steuerung_Eckwerte!B27,Daten!$C$26:$C$429,0))=0, " ", INDEX(Daten!$H$26:$H$429,MATCH(Steuerung_Eckwerte!B27,Daten!$C$26:$C$429,0)))
A28: 09418 | B28: JC Altenburger Land | C28: =CONCATENATE(B28, " ", $D$3, " ", F28) -> JC Altenburger Land (Gebietsstand Dezember 2024) | F28: =IF(INDEX(Daten!$H$26:$H$429,MATCH(Steuerung_Eckwerte!B28,Daten!$C$26:$C$429,0))=0, " ", INDEX(Daten!$H$26:$H$429,MATCH(Steuerung_Eckwerte!B28,Daten!$C$26:$C$429,0)))
A29: 54702 | B29: JC Altenkirchen (Westerwald) | C29: =CONCATENATE(B29, " ", $D$3, " ", F29) -> JC Altenkirchen (Westerwald) (Gebietsstand Dezember 2024) | F29: =IF(INDEX(Daten!$H$26:$H$429,MATCH(Steuerung_Eckwerte!B29,Daten!$C$26:$C$429,0))=0, " ", INDEX(Daten!$H$26:$H$429,MATCH(Steuerung_Eckwerte!B29,Daten!$C$26:$C$429,0)))
A30: 04846 | B30: JC Altmarkkreis Salzwedel | C30: =CONCATENATE(B30, " ", $D$3, " ", F30) -> JC Altmarkkreis Salzwedel (Gebietsstand Dezember 2024) | F30: =IF(INDEX(Daten!$H$26:$H$429,MATCH(Steuerung_Eckwerte!B30,Daten!$C$26:$C$429,0))=0, " ", INDEX(Daten!$H$26:$H$429,MATCH(Steuerung_Eckwerte!B30,Daten!$C$26:$C$429,0)))
A31: 85906 | B31: JC Altötting | C31: =CONCATENATE(B31, " ", $D$3, " ", F31) -> JC Altötting (Gebietsstand Dezember 2024) | F31: =IF(INDEX(Daten!$H$26:$H$429,MATCH(Steuerung_Eckwerte!B31,Daten!$C$26:$C$429,0))=0, " ", INDEX(Daten!$H$26:$H$429,MATCH(Steuerung_Eckwerte!B31,Daten!$C$26:$C$429,0)))
A32: 52704 | B32: JC Alzey-Worms | C32: =CONCATENATE(B32, " ", $D$3, " ", F32) -> JC Alzey-Worms (Gebietsstand Dezember 2024) | F32: =IF(INDEX(Daten!$H$26:$H$429,MATCH(Steuerung_Eckwerte!B32,Daten!$C$26:$C$429,0))=0, " ", INDEX(Daten!$H$26:$H$429,MATCH(Steuerung_Eckwerte!B32,Daten!$C$26:$C$429,0)))
A33: 74302 | B33: JC Amberg-Sulzbach | C33: =CONCATENATE(B33, " ", $D$3, " ", F33) -> JC Amberg-Sulzbach (Gebietsstand Dezember 2024) | F33: =IF(INDEX(Daten!$H$26:$H$429,MATCH(Steuerung_Eckwerte!B33,Daten!$C$26:$C$429,0))=0, " ", INDEX(Daten!$H$26:$H$429,MATCH(Steuerung_Eckwerte!B33,Daten!$C$26:$C$429,0)))
A34: 26112 | B34: JC Ammerland | C34: =CONCATENATE(B34, " ", $D$3, " ", F34) -> JC Ammerland (Gebietsstand Dezember 2024) | F34: =IF(INDEX(Daten!$H$26:$H$429,MATCH(Steuerung_Eckwerte!B34,Daten!$C$26:$C$429,0))=0, " ", INDEX(Daten!$H$26:$H$429,MATCH(Steuerung_Eckwerte!B34,Daten!$C$26:$C$429,0)))
A35: 04208 | B35: JC Anhalt-Bitterfeld | C35: =CONCATENATE(B35, " ", $D$3, " ", F35) -> JC Anhalt-Bitterfeld (Gebietsstand Dezember 2024) | F35: =IF(INDEX(Daten!$H$26:$H$429,MATCH(Steuerung_Eckwerte!B35,Daten!$C$26:$C$429,0))=0, " ", INDEX(Daten!$H$26:$H$429,MATCH(Steuerung_Eckwerte!B35,Daten!$C$26:$C$429,0)))
